Workbook
Name CAC_Values: #REF!
Name Channels_CAC: #REF!

Sheet Financial Projections
J2: Our Financial Model centers around charging merchants a .75% fee for using one card. Initially, for our first year, we will not have any full-time employees and just contract the card and digital development out. Once we find a product-market fit we will hire our first employees. The biggest expenses we see initially are marketing and development of the card. After we start hiring employees that will be the majority of expenses.
C4: Basic Financial Inventory
C5: How will you make & spend money?
C9: YEAR 1 | K9: YEAR 2 | Q9: YEAR 3
Z12: Revenue and Expenses
C13: Annual Revenue | K13: Annual Revenue | Q13: Annual Revenue | Z13: Year 1 | AA13: Year 2 | AB13: Year 3
Y14: Revenue | Z14: =F24 -> 432000 | AA14: =N24 -> 972000 | AB14: =T24 -> 2187000
C15: Customer Annual Value | K15: Customer Annual Value | Q15: Customer Annual Value | Y15: COGS | Z15: =F69 -> 597827.94 | AA15: =N69 -> 984443.61 | AB15: =T69 -> 1389051.6
C16: How much revenue do you estimate your company will make for each customer? | K16: How much revenue do you estimate your company will make for each customer? | Q16: How much revenue do you estimate your company will make for each customer? | Y16: Net | Z16: =Z14-Z15 -> -165827.94 | AA16: =AA14-AA15 -> -12443.612 | AB16: =AB14-AB15 -> 797948.36
C17: Product Price | F17: % | K17: Product Price | N17: % | Q17: Product Price | T17: %
C18: Price for end customers | F18: 0.005 | K18: =C18 -> Price for end customers | N18: 0.005 | Q18: =C18 -> Price for end customers | T18: 0.005
C19: Price for merchants | F19: ='Breakdown and References Year 1'!B4 -> 0.0075 | K19: =C19 -> Price for merchants | N19: =F19 -> 0.0075 | Q19: =C19 -> Price for merchants | T19: =F19 -> 0.0075
C20: Annual Purchases | F20: $ Purchases | K20: Annual Purchases | N20: $ Purchases | Q20: Annual Purchases | T20: $ Purchases
C21: Amount of purchases an average customer will make in a year. | F21: ='Breakdown and References Year 1'!C4 -> 3600 | K21: Amount of purchases an average customer will make in a year. | N21: =F21*'Breakdown and References Year 1'!B54 -> 4500 | Q21: Number of purchases an average customer will make in a year. | T21: =N21*'Breakdown and References Year 1'!B54 -> 5625
C22: Number of Customers | K22: Number of Customers | Q22: Number of Customers
C23: Amount of purchases an average customer will make in a year. | F23: ='Breakdown and References Year 1'!E3 -> 16000 | K23: Amount of purchases an average customer will make in a year. | N23: =F23*'Breakdown and References Year 1'!B57 -> 28800 | Q23: Number of purchases an average customer will make in a year. | T23: =N23*'Breakdown and References Year 1'!B57 -> 51840
C24: Total Revenue | F24: =F19*F23*F21 -> 432000 | K24: Total Revenue | N24: =N19*N23*N21 -> 972000 | Q24: Total Revenue | T24: =T19*T23*T21 -> 2187000
C29: Annual Expenses | K29: Annual Expenses | Q29: Annual Expenses
C31: Salaries | K31: Salaries | Q31: Salaries
C32: What will your future full time employees salary (and yours) be? | K32: What will your future full time employees salary (and yours) be? | Q32: What will your future full time employees salary (and yours) be?
C33: Average Salary | E33: Salary | F33: Team Size | K33: Average Salary | M33: Salary | N33: Team Size | Q33: Average Salary | S33: Salary | T33: Team Size
C34: What's the average salary you and your team members will make each year? | E34: ='Breakdown and References Year 1'!C11 -> 107983.33 | F34: ='Breakdown and References Year 1'!E11 -> 3 | K34: What's the average salary you and your team members will make each year? | M34: =E34 -> 107983.33 | N34: =F34+2 -> 5 | Q34: What's the average salary you and your team members will make each year? | S34: =E34 -> 107983.33 | T34: =N34+2 -> 7
C35: Subtotal - Salaries | E35: =SUMPRODUCT(E34, F34) -> 323950 | K35: Subtotal - Salaries | M35: =SUMPRODUCT(M34, N34) -> 539916.67 | Q35: Subtotal - Salaries | S35: =SUMPRODUCT(S34, T34) -> 755883.33
C36: Taxes | F36: % | K36: Taxes | N36: % | Q36: Taxes | T36: %
C37: Consider about 33% of the net salary (25% of gross salary) for: Federal taxes, Social Security and Medicare taxes. For specific and detailed calculations, expand the + here on the left side column. | F37: 0.3333 | K37: Consider about 33% of the net salary (25% of gross salary) for: Federal taxes, Social Security and Medicare taxes. For specific and detailed calculations, expand the + here on the left side column. | N37: 0.3333 | Q37: Consider about 33% of the net salary (25% of gross salary) for: Federal taxes, Social Security and Medicare taxes. For specific and detailed calculations, expand the + here on the left side column. | T37: 0.3333
C38: Resources: https://www.thebalancesmb.com/payroll-taxes-3193126 http://web.mit.edu/e-club/hadzima/how-much-does-an-employee-cost.html | K38: Resources: https://www.thebalancesmb.com/payroll-taxes-3193126 http://web.mit.edu/e-club/hadzima/how-much-does-an-employee-cost.html | Q38: Resources: https://www.thebalancesmb.com/payroll-taxes-3193126 http://web.mit.edu/e-club/hadzima/how-much-does-an-employee-cost.html
C39: Benefits Package | F39: % | K39: Benefits Package | N39: % | Q39: Benefits Package | T39: %
C40: Consider about 30% of the net salary for benefits costs, such as paid leave (vacation, holidays, sick leave and personal), average employer contribution to retirement, etc. | F40: 0.3 | K40: Consider about 30% of the net salary for benefits costs, such as paid leave (vacation, holidays, sick leave and personal), average employer contribution to retirement, etc. | N40: 0.3 | Q40: Consider about 30% of the net salary for benefits costs, such as paid leave (vacation, holidays, sick leave and personal), average employer contribution to retirement, etc. | T40: 0.3
C41: Resources: https://www.bankrate.com/finance/financial-literacy/the-value-of-employer-benefits.aspx https://www.griffinbenefits.com/employeebenefitsblog/what-does-the-average-employer-spend-on-employee-benefits | K41: Resources: https://www.bankrate.com/finance/financial-literacy/the-value-of-employer-benefits.aspx https://www.griffinbenefits.com/employeebenefitsblog/what-does-the-average-employer-spend-on-employee-benefits | Q41: Resources: https://www.bankrate.com/finance/financial-literacy/the-value-of-employer-benefits.aspx https://www.griffinbenefits.com/employeebenefitsblog/what-does-the-average-employer-spend-on-employee-benefits
C42: Total Compensation | E42: =E35 * (1 + F37 + F40) -> 529107.54 | K42: Total Compensation | M42: =M35 * (1 + N37 + N40) -> 881845.89 | Q42: Total Compensation | S42: =S35 * (1 + T37 + T40) -> 1234584.2
C45: Marketing | K45: Marketing | Q45: Marketing
C46: How much do you estimate your company will need to spend to acquire customers? | K46: How much do you estimate your company will need to spend to acquire customers? | Q46: How much do you estimate your company will need to spend to acquire customers?
C47: Marketing Costs | F47: $ | K47: Marketing Costs | N47: $ | Q47: Marketing Costs | T47: $
C48: How big do you expect your marketing costs to be? Examples: $1,000 - Get a logo and a basic website $50,000 - Get all of the above plus advertising $100,000 - Get all of the above plus a simple app $500,000 - Get all of the above plus a complex app | F48: ='Breakdown and References Year 1'!F22 -> 50730 | K48: How big do you expect your marketing costs to be? Examples: $1,000 - Get a logo and a basic website $50,000 - Get all of the above plus advertising $100,000 - Get all of the above plus a simple app $500,000 - Get all of the above plus a complex app | N48: =F48*1.5 -> 76095 | Q48: How big do you expect your marketing costs to be? Examples: $1,000 - Get a logo and a basic website $50,000 - Get all of the above plus advertising $100,000 - Get all of the above plus a simple app $500,000 - Get all of the above plus a complex app | T48: =N48*1.5 -> 114142.5
C51: 6. Operational | K51: 6. Operational | Q51: 6. Operational
C52: How much do you estimate your company will spend to operate? | K52: How much do you estimate your company will spend to operate? | Q52: How much do you estimate your company will spend to operate?
C53: Administration | F53: $ | K53: Administration | N53: $ | Q53: Administration | T53: $
C54: Legal, attorney, CPA/tax advisor and other professional consultants fees, insurances, etc... Consider about $5000 annually. For specific and detailed calculations, expand the + here on the left side column. | F54: ='Breakdown and References Year 1'!F25 -> 10000 | K54: Legal, attorney, CPA/tax advisor and other professional consultants fees, insurances, etc... Consider about $5000 annually. For specific and detailed calculations, expand the + here on the left side column. | N54: =F54*1.5 -> 15000 | Q54: Legal, attorney, CPA/tax advisor and other professional consultants fees, insurances, etc... Consider about $5000 annually. For specific and detailed calculations, expand the + here on the left side column. | T54: =N54*1.5 -> 22500
C55: According to https://www.score.org/resource/infographic-look-accounting-and-taxes : 23% of small business owners spend $1,000 or less 31% Spend $1,000 to $5,000 18% Spend $5,000 to $10,000 12% Spend $10,000 to $20,000 16% Spend $20,000 or more | K55: According to https://www.score.org/resource/infographic-look-accounting-and-taxes : 23% of small business owners spend $1,000 or less 31% Spend $1,000 to $5,000 18% Spend $5,000 to $10,000 12% Spend $10,000 to $20,000 16% Spend $20,000 or more | Q55: According to https://www.score.org/resource/infographic-look-accounting-and-taxes : 23% of small business owners spend $1,000 or less 31% Spend $1,000 to $5,000 18% Spend $5,000 to $10,000 12% Spend $10,000 to $20,000 16% Spend $20,000 or more
C56: Resources: CPA, Accountant https://www.cpapracticeadvisor.com/news/12300091/survey-shows-average-fees-for-accounting-tax-firm-services-for-2017 https://baranovcpa.ca/how-much-do-accountants-charge-for-a-small-business/ Insurances https://www.insureon.com/small-business-insurance/general-liability/cost https://fitsmallbusiness.com/commercial-property-insurance/ | K56: Resources: CPA, Accountant https://www.cpapracticeadvisor.com/news/12300091/survey-shows-average-fees-for-accounting-tax-firm-services-for-2017 https://baranovcpa.ca/how-much-do-accountants-charge-for-a-small-business/ Insurances https://www.insureon.com/small-business-insurance/general-liability/cost https://fitsmallbusiness.com/commercial-property-insurance/ | Q56: Resources: CPA, Accountant https://www.cpapracticeadvisor.com/news/12300091/survey-shows-average-fees-for-accounting-tax-firm-services-for-2017 https://baranovcpa.ca/how-much-do-accountants-charge-for-a-small-business/ Insurances https://www.insureon.com/small-business-insurance/general-liability/cost https://fitsmallbusiness.com/commercial-property-insurance/
...

Sheet Breakdown and References Year 1
A1: Entity | B1: Rate (%) | C1: Cost/Price (or average) per unit ($) | D1: Base Price | E1: Size/ Quantity | F1: Total | G1: Reference Hyperlinks | H1: Comments | I1: Additional
A2: Revenue
A3: Retail price for end customers | B3: 0 | C3: 0 | D3: 0 | E3: 16000 | F3: =D3+E3*C3*B3 -> 0 | H3: We do not charge directly to the customers since this competitor space does not charge a fee to the customer.
A4: Price for merchants | B4: 0.0075 | C4: =300*12 -> 3600 | D4: 0 | E4: =E3 -> 16000 | F4: =D4+E4*C4*B4 -> 432000 | G4: https://merchantcostconsulting.com/lower-credit-card-processing-fees/paypal-and-venmo-fees-rate-increases-and-updates/ | H4: Comparing Venmo (1.75%), apple pay (1.7%) | I4: https://www.applemust.com/how-apple-pay-makes-money-merchant-transaction-fees/
A5: Revenue from Analytics (Alternative not considered) | B5: NA | C5: 9.52 | D5: 0 | E5: =E3*0.99 -> 15840 | F5: =D5+C5*E5 -> 150796.8 | G5: https://www.invisibly.com/learn-blog/how-much-is-data-worth/ | H5: Average banking data per user 9.52$
A6: Price for Physical card delivery | B6: NA | C6: =C27+C28+C29+3 -> 16.2 | D6: 0 | E6: =0.02*E3 -> 320 | F6: =D6+E6*C6 -> 5184 | G6: https://www.paytmbank.com/ratesCharges | H6: Comparing to card issuance charges of similar company | I6: https://www.businessinsider.in/business/corporates/news/paytm-payments-bank-overachieved-its-target-of-issuing-visa-debit-cards-at-7-million-in-fy21-as-against-goal-of-1-million/articleshow/89918699.cms
A7: Control of privacy | B7: NA | C7: =C5 -> 9.52 | D7: 0 | E7: =E3-E5 -> 160 | F7: =D7+E7*C7 -> 1523.2 | G7: https://www.digitaljournal.com/business/report-finds-only-1-percent-reads-terms-conditions/article/566127 | H7: Alternative. We give an option of privacy control. Privacy is a growing concern. But also operate typically as other competitors in the space.
A8: Total | F8: =SUM(F3:F4) -> 432000 | H8: Not considering revenue of analytics due to privacy concerns.
A9: Expenses
A10: Salaries
A11: Average Salary (Breakdown provided as follows) | B11: NA | C11: =AVERAGE(C12:C14) -> 107983.33 | D11: NA | E11: =SUM(E12:E14) -> 3 | F11: =E11*C11 -> 323950 | H11: Salries considered for various roles from sources provided in links.
A12: Software Developer | B12: NA | C12: 89000 | D12: NA | E12: 1 | F12: =E12*C12 -> 89000 | G12: https://www.payscale.com/research/US/Job=Software_Engineer/Salary | H12: Software dev for features in perpetuity and bug fixes.
A13: Software Quality Engineer | B13: NA | C13: 99657 | D13: NA | E13: 1 | F13: =C13*E13 -> 99657 | G13: https://www.salary.com/research/salary/recruiting/software-qa-engineer-salary | H13: QA for maintaining quality of the app and the website.
A14: Hardware Engineer | B14: NA | C14: 135293 | D14: NA | E14: 1 | F14: =E14*C14 -> 135293 | G14: https://builtin.com/salaries/dev-engineer/hardware-engineer | H14: Hardware engineer to design and test the physical card.
A15: Taxes | B15: 0.33333333 | C15: NA | D15: NA | E15: NA
A16: Benefits | B16: 0.3 | C16: NA | D16: NA | E16: NA
A17: Net Total | F17: =F11*(1+B15+B16) -> 529118.33
A18: Marketing (In-house using social media tools)
A19: Facebook and Instagram (CPM) | B19: NA | C19: =6.7+7.19 -> 13.89 | D19: 0 | E19: 3000 | F19: =D19+C19*E19 -> 41670 | G19: https://www.k6agency.com/instagram-ads-cost/ | H19: Considered cost per thousand impressions. Typical expense taken from the template.
A20: Google Search | B20: NA | C20: 3 | D20: 0 | E20: =E19 -> 3000 | F20: =D20+C20*E20 -> 9000 | G20: https://www.wordstream.com/blog/ws/2015/05/21/how-much-does-adwords-cost
A21: YouTube | B21: NA | C21: 0.02 | D21: 0 | E21: =E19 -> 3000 | F21: =D21+C21*E21 -> 60 | G21: https://graphy.com/blog/youtube-ads-cost/
A22: Total | F22: =SUM(F19:F21) -> 50730
A23: Legal and Financial Services (Outsourced)
A24: Legal, Attorney and financial advisor | B24: NA | C24: 10000 | D24: 0 | E24: 1 | F24: =D24+C24*E24 -> 10000 | H24: Fees figure taken from the template.
A25: Total | F25: =SUM(F24) -> 10000
A26: Card Development (Outsourced)
A27: Card production cost | B27: NA | C27: 1.5 | D27: 0 | E27: =E6 -> 320 | F27: =D27+C27*E27 -> 480 | G27: https://www.credit.com/blog/how-a-credit-card-is-made-74903/ | H27: Card development would be outsourced or given a contract to.
A28: Shipping | B28: NA | C28: 8.5 | D28: 0 | E28: =E6 -> 320 | F28: =D28+C28*E28 -> 2720 | G28: https://www.usps.com/ship/priority-mail.htm
A29: Packaging | B29: NA | C29: 3.2 | D29: 0 | E29: =E6 -> 320 | F29: =D29+C29*E29 -> 1024
A30: Total | F30: =SUM(F27:F29) -> 4224
A31: Digital Development (In-house)
A32: Firebase | B32: NA | C32: 0.026 | D32: 0 | E32: =2*E3/5 -> 6400 | F32: =D32+C32*E32 -> 166.4 | G32: https://firebase.google.com/pricing | H32: 6000 is the units required. 1 account would take up 2 gb of space. 0.026 per 5gb storage.
A33: AWS - (size per account) | F33: =D33+C33*E33 -> 0 | H33: Not used initially where the customer count is low. Using a cheaper option till then.
A34: Additional Software Security | B34: NA | C34: 300 | D34: 0 | E34: 12 | F34: =D34+C34*E34 -> 3600 | G34: https://www.provendatarecovery.com/blog/cyber-security-cost-expenses-fees/
A35: Total | F35: =F32+F34 -> 3766.4
A36: Point of Sale Device (Note: These are future development costs not included in the current plan)
A37: Research and Development - POS (Point of Sale Device) Prototype | C37: 160 | D37: 0 | E37: 2 | F37: =D37+C37*E37 -> 320 | G37: Hardware cost for Prototype development (Prices from amazon)
A38: POS - Hardware Design | C38: 10000 | E38: =1 -> 1 | F38: =D38+C38*E38 -> 10000 | G38: https://www.cadcrowd.com/blog/how-much-does-product-design-cost-what-are-prices-for-freelance-design-firms/
A39: POS - Manufacturing Cost | C39: 45 | D39: 70000 | E39: =100 -> 100 | F39: =D39+C39*E39 -> 74500 | G39: https://axonim.com/blog/electronics-development-cost-estimation.html
A40: POS - Certification | C40: 10000 | E40: 1 | F40: =D40+C40*E40 -> 10000 | G40: https://www.integrasources.com/blog/guide-consumer-electronics-certification-us-eu-requirements-consider-mass-production/
...

Sheet Breakdown and References Year 2
A1: Entity | B1: Rate (%) | C1: Cost/Price (or average) per unit ($) | D1: Base Price | E1: Size/ Quantity | F1: Total | G1: Reference Hyperlinks | H1: Comments | I1: Additional
A2: Revenue
A3: Retail price for end customers | B3: 0 | C3: 0 | D3: 0 | E3: 28800 | F3: =D3+E3*C3*B3 -> 0 | H3: We do not charge directly to the customers since this competitor space does not charge a fee to the customer.
A4: Price for merchants | B4: 0.0075 | C4: ='Financial Projections'!N21 -> 4500 | D4: 0 | E4: =E3 -> 28800 | F4: =D4+E4*C4*B4 -> 972000 | G4: https://merchantcostconsulting.com/lower-credit-card-processing-fees/paypal-and-venmo-fees-rate-increases-and-updates/ | H4: Comparing Venmo (1.75%), apple pay (1.7%) | I4: https://www.applemust.com/how-apple-pay-makes-money-merchant-transaction-fees/
A5: Revenue from Analytics (Alternative not considered) | B5: NA | C5: 9.52 | D5: 0 | E5: =E3*0.99 -> 28512 | F5: =D5+C5*E5 -> 271434.24 | G5: https://www.invisibly.com/learn-blog/how-much-is-data-worth/ | H5: Average banking data per user 9.52$
A6: Price for Physical card delivery | B6: NA | C6: =C27+C28+C29+3 -> 16.2 | D6: 0 | E6: =0.02*E3 -> 576 | F6: =D6+E6*C6 -> 9331.2 | G6: https://www.paytmbank.com/ratesCharges | H6: Comparing to card issuance charges of similar company | I6: https://www.businessinsider.in/business/corporates/news/paytm-payments-bank-overachieved-its-target-of-issuing-visa-debit-cards-at-7-million-in-fy21-as-against-goal-of-1-million/articleshow/89918699.cms
A7: Control of privacy | B7: NA | C7: =C5 -> 9.52 | D7: 0 | E7: =E3-E5 -> 288 | F7: =D7+E7*C7 -> 2741.76 | G7: https://www.digitaljournal.com/business/report-finds-only-1-percent-reads-terms-conditions/article/566127 | H7: We give an option of privacy control. Privacy is a growing concern. But also operate typically as other competitors in the space.
A8: Total | F8: =SUM(F3:F4) -> 972000 | H8: Not considering revenue of analytics due to privacy concerns.
A9: Expenses
A10: Salaries
A11: Average Salary (Breakdown provided as follows) | B11: NA | C11: =AVERAGE(C12:C14) -> 107983.33 | D11: NA | E11: ='Financial Projections'!N34 -> 5 | F11: =E11*C11 -> 539916.67 | H11: Salries considered for various roles from sources provided in links.
A12: Software Developer | B12: NA | C12: 89000 | D12: NA | E12: 1 | F12: =E12*C12 -> 89000 | G12: https://www.payscale.com/research/US/Job=Software_Engineer/Salary | H12: Software dev for features in perpetuity and bug fixes.
A13: Software Quality Engineer | B13: NA | C13: 99657 | D13: NA | E13: 1 | F13: =C13*E13 -> 99657 | G13: https://www.salary.com/research/salary/recruiting/software-qa-engineer-salary | H13: QA for maintaining quality of the app and the website.
A14: Hardware Engineer | B14: NA | C14: 135293 | D14: NA | E14: 1 | F14: =E14*C14 -> 135293 | G14: https://builtin.com/salaries/dev-engineer/hardware-engineer | H14: Hardware engineer to design and test the physical card.
A15: Taxes | B15: 0.33333333 | C15: NA | D15: NA | E15: NA
A16: Benefits | B16: 0.3 | C16: NA | D16: NA | E16: NA
A17: Net Total | F17: =F11*(1+B15+B16) -> 881863.89
A18: Marketing (In-house using social media tools)
A19: Facebook and Instagram (CPM) | B19: NA | C19: =6.7+7.19 -> 13.89 | D19: 0 | E19: 3000 | F19: =D19+C19*E19 -> 41670 | G19: https://www.k6agency.com/instagram-ads-cost/ | H19: Considered cost per thousand impressions. Typical expense taken from the template.
A20: Google Search | B20: NA | C20: 3 | D20: 0 | E20: =E19 -> 3000 | F20: =D20+C20*E20 -> 9000 | G20: https://www.wordstream.com/blog/ws/2015/05/21/how-much-does-adwords-cost
A21: YouTube | B21: NA | C21: 0.02 | D21: 0 | E21: =E19 -> 3000 | F21: =D21+C21*E21 -> 60 | G21: https://graphy.com/blog/youtube-ads-cost/
A22: Total | F22: =SUM(F19:F21) -> 50730
A23: Legal and Financial Services (Outsourced)
A24: Legal, Attorney and financial advisor | B24: NA | C24: 10000 | D24: 0 | E24: 1 | F24: =D24+C24*E24 -> 10000 | H24: Fees figure taken from the template.
A25: Total | F25: =SUM(F24) -> 10000
A26: Card Development (Outsourced)
A27: Card production cost | B27: NA | C27: 1.5 | D27: 0 | E27: =E6 -> 576 | F27: =D27+C27*E27 -> 864 | G27: https://www.credit.com/blog/how-a-credit-card-is-made-74903/ | H27: Card development would be outsourced or given a contract to.
A28: Shipping | B28: NA | C28: 8.5 | D28: 0 | E28: =E6 -> 576 | F28: =D28+C28*E28 -> 4896 | G28: https://www.usps.com/ship/priority-mail.htm
A29: Packaging | B29: NA | C29: 3.2 | D29: 0 | E29: =E6 -> 576 | F29: =D29+C29*E29 -> 1843.2
A30: Total | F30: =SUM(F27:F29) -> 7603.2
A31: Digital Development (In-house)
A32: Firebase | B32: NA | C32: 0.026 | D32: 0 | E32: =2*E3/5 -> 11520 | F32: =D32+C32*E32 -> 299.52 | G32: https://firebase.google.com/pricing | H32: 6000 is the units required. 1 account would take up 2 gb of space. 0.026 per 5gb storage.
A33: AWS - (size per account) | F33: =D33+C33*E33 -> 0 | H33: Not used initially where the customer count is low. Using a cheaper option till then.
A34: Additional Software Security | B34: NA | C34: 300 | D34: 0 | E34: 12 | F34: =D34+C34*E34 -> 3600 | G34: https://www.provendatarecovery.com/blog/cyber-security-cost-expenses-fees/
A35: Total | F35: =F32+F34 -> 3899.52
A36: Point of Sale Device (Note: These are future development costs not included in the current plan)
A37: Research and Development - POS (Point of Sale Device) Prototype | C37: 160 | D37: 0 | E37: 2 | F37: =D37+C37*E37 -> 320 | G37: Hardware cost for Prototype development (Prices from amazon)
A38: POS - Hardware Design | C38: 10000 | E38: =1 -> 1 | F38: =D38+C38*E38 -> 10000 | G38: https://www.cadcrowd.com/blog/how-much-does-product-design-cost-what-are-prices-for-freelance-design-firms/
A39: POS - Manufacturing Cost | C39: 45 | D39: 70000 | E39: =100 -> 100 | F39: =D39+C39*E39 -> 74500 | G39: https://axonim.com/blog/electronics-development-cost-estimation.html
A40: POS - Certification | C40: 10000 | E40: 1 | F40: =D40+C40*E40 -> 10000 | G40: https://www.integrasources.com/blog/guide-consumer-electronics-certification-us-eu-requirements-consider-mass-production/
...

Sheet Breakdown and References Year 3
A1: Entity | B1: Rate (%) | C1: Cost/Price (or average) per unit ($) | D1: Base Price | E1: Size/ Quantity | F1: Total | G1: Reference Hyperlinks | H1: Comments | I1: Additional
A2: Revenue
A3: Retail price for end customers | B3: 0 | C3: 0 | D3: 0 | E3: ='Financial Projections'!T23 -> 51840 | F3: =D3+E3*C3*B3 -> 0 | H3: We do not charge directly to the customers since this competitor space does not charge a fee to the customer.
A4: Price for merchants | B4: 0.0075 | C4: ='Financial Projections'!T21 -> 5625 | D4: 0 | E4: =E3 -> 51840 | F4: =D4+E4*C4*B4 -> 2187000 | G4: https://merchantcostconsulting.com/lower-credit-card-processing-fees/paypal-and-venmo-fees-rate-increases-and-updates/ | H4: Comparing Venmo (1.75%), apple pay (1.7%) | I4: https://www.applemust.com/how-apple-pay-makes-money-merchant-transaction-fees/
A5: Revenue from Analytics (Alternative not considered) | B5: NA | C5: 9.52 | D5: 0 | E5: =E3*0.99 -> 51321.6 | F5: =D5+C5*E5 -> 488581.63 | G5: https://www.invisibly.com/learn-blog/how-much-is-data-worth/ | H5: Average banking data per user 9.52$
A6: Price for Physical card delivery | B6: NA | C6: =C27+C28+C29+3 -> 16.2 | D6: 0 | E6: =0.02*E3 -> 1036.8 | F6: =D6+E6*C6 -> 16796.16 | G6: https://www.paytmbank.com/ratesCharges | H6: Comparing to card issuance charges of similar company | I6: https://www.businessinsider.in/business/corporates/news/paytm-payments-bank-overachieved-its-target-of-issuing-visa-debit-cards-at-7-million-in-fy21-as-against-goal-of-1-million/articleshow/89918699.cms
A7: Control of privacy | B7: NA | C7: =C5 -> 9.52 | D7: 0 | E7: =E3-E5 -> 518.4 | F7: =D7+E7*C7 -> 4935.168 | G7: https://www.digitaljournal.com/business/report-finds-only-1-percent-reads-terms-conditions/article/566127 | H7: We give an option of privacy control. Privacy is a growing concern. But also operate typically as other competitors in the space.
A8: Total | F8: =SUM(F3:F4) -> 2187000 | H8: Not considering revenue of analytics due to privacy concerns.
A9: Expenses
A10: Salaries
A11: Average Salary (Breakdown provided as follows) | B11: NA | C11: =AVERAGE(C12:C14) -> 107983.33 | D11: NA | E11: ='Financial Projections'!T34 -> 7 | F11: =E11*C11 -> 755883.33 | H11: Salries considered for various roles from sources provided in links.
A12: Software Developer | B12: NA | C12: 89000 | D12: NA | E12: 1 | F12: =E12*C12 -> 89000 | G12: https://www.payscale.com/research/US/Job=Software_Engineer/Salary | H12: Software dev for features in perpetuity and bug fixes.
A13: Software Quality Engineer | B13: NA | C13: 99657 | D13: NA | E13: 1 | F13: =C13*E13 -> 99657 | G13: https://www.salary.com/research/salary/recruiting/software-qa-engineer-salary | H13: QA for maintaining quality of the app and the website.
A14: Hardware Engineer | B14: NA | C14: 135293 | D14: NA | E14: 1 | F14: =E14*C14 -> 135293 | G14: https://builtin.com/salaries/dev-engineer/hardware-engineer | H14: Hardware engineer to design and test the physical card.
A15: Taxes | B15: 0.33333333 | C15: NA | D15: NA | E15: NA
A16: Benefits | B16: 0.3 | C16: NA | D16: NA | E16: NA
A17: Net Total | F17: =F11*(1+B15+B16) -> 1234609.4
A18: Marketing (In-house using social media tools)
A19: Facebook and Instagram (CPM) | B19: NA | C19: =6.7+7.19 -> 13.89 | D19: 0 | E19: 3000 | F19: =D19+C19*E19 -> 41670 | G19: https://www.k6agency.com/instagram-ads-cost/ | H19: Considered cost per thousand impressions. Typical expense taken from the template.
A20: Google Search | B20: NA | C20: 3 | D20: 0 | E20: =E19 -> 3000 | F20: =D20+C20*E20 -> 9000 | G20: https://www.wordstream.com/blog/ws/2015/05/21/how-much-does-adwords-cost
A21: YouTube | B21: NA | C21: 0.02 | D21: 0 | E21: =E19 -> 3000 | F21: =D21+C21*E21 -> 60 | G21: https://graphy.com/blog/youtube-ads-cost/
A22: Total | F22: =SUM(F19:F21) -> 50730
A23: Legal and Financial Services (Outsourced)
A24: Legal, Attorney and financial advisor | B24: NA | C24: 10000 | D24: 0 | E24: 1 | F24: =D24+C24*E24 -> 10000 | H24: Fees figure taken from the template.
A25: Total | F25: =SUM(F24) -> 10000
A26: Card Development (Outsourced)
A27: Card production cost | B27: NA | C27: 1.5 | D27: 0 | E27: =E6 -> 1036.8 | F27: =D27+C27*E27 -> 1555.2 | G27: https://www.credit.com/blog/how-a-credit-card-is-made-74903/ | H27: Card development would be outsourced or given a contract to.
A28: Shipping | B28: NA | C28: 8.5 | D28: 0 | E28: =E6 -> 1036.8 | F28: =D28+C28*E28 -> 8812.8 | G28: https://www.usps.com/ship/priority-mail.htm
A29: Packaging | B29: NA | C29: 3.2 | D29: 0 | E29: =E6 -> 1036.8 | F29: =D29+C29*E29 -> 3317.76
A30: Total | F30: =SUM(F27:F29) -> 13685.76
A31: Digital Development (In-house)
A32: Firebase | B32: NA | C32: 0.026 | D32: 0 | E32: =2*E3/5 -> 20736 | F32: =D32+C32*E32 -> 539.136 | G32: https://firebase.google.com/pricing | H32: 6000 is the units required. 1 account would take up 2 gb of space. 0.026 per 5gb storage.
A33: AWS - (size per account) | F33: =D33+C33*E33 -> 0 | H33: Not used initially where the customer count is low. Using a cheaper option till then.
A34: Additional Software Security | B34: NA | C34: 300 | D34: 0 | E34: 12 | F34: =D34+C34*E34 -> 3600 | G34: https://www.provendatarecovery.com/blog/cyber-security-cost-expenses-fees/
A35: Total | F35: =F32+F34 -> 4139.136
A36: Point of Sale Device (Note: These are future development costs not included in the current plan)
A37: Research and Development - POS (Point of Sale Device) Prototype | C37: 160 | D37: 0 | E37: 2 | F37: =D37+C37*E37 -> 320 | G37: Hardware cost for Prototype development (Prices from amazon)
A38: POS - Hardware Design | C38: 10000 | E38: =1 -> 1 | F38: =D38+C38*E38 -> 10000 | G38: https://www.cadcrowd.com/blog/how-much-does-product-design-cost-what-are-prices-for-freelance-design-firms/
A39: POS - Manufacturing Cost | C39: 45 | D39: 70000 | E39: =100 -> 100 | F39: =D39+C39*E39 -> 74500 | G39: https://axonim.com/blog/electronics-development-cost-estimation.html
A40: POS - Certification | C40: 10000 | E40: 1 | F40: =D40+C40*E40 -> 10000 | G40: https://www.integrasources.com/blog/guide-consumer-electronics-certification-us-eu-requirements-consider-mass-production/
...

Sheet Variables
A1: Marketing Cost Options
A2: 1000
A3: 50000
A4: 100000
A5: 500000
