Workbook
Name CAC_Values: #REF!
Name Channels_CAC: #REF!

Sheet Example
C4: Basic Financial Inventory
C5: How will you make & spend money?
C9: This spreadsheet will help you estimate how much money your business will make, and spend.
C13: Annual Revenue
C15: Customer Annual Value
C16: How much revenue do you estimate your company will make for each customer?
C17: Product Price | F17: $
C18: The price of your product that you developed during your Science of Pricing exercise. | F18: 49
C19: Annual Purchases | F19: # Purchases
C20: Number of purchases an average customer will make in a year. | F20: 1
C21: Total Revenue | F21: =F18*F20 -> 49
C26: Annual Expenses
C28: Salaries
C29: What will your future full time employees salary (and yours) be?
C30: Average Salary | E30: Salary | F30: Team Size
C31: What's the average salary you and your team members will make each year? | E31: 100000 | F31: 2
C32: Subtotal - Salaries | E32: =SUMPRODUCT(E31, F31) -> 200000
C33: Taxes | F33: %
C34: Consider about 33% of the net salary (25% of gross salary) for: Federal taxes, Social Security and Medicare taxes. For specific and detailed calculations, expand the + here on the left side column. | F34: 0.3333
C35: Calculator: https://salaryaftertax.com/us Resources: https://www.thebalancesmb.com/payroll-taxes-3193126 http://web.mit.edu/e-club/hadzima/how-much-does-an-employee-cost.html
C36: Benefits Package | F36: %
C37: Consider about 30% of the net salary for benefits costs, such as paid leave (vacation, holidays, sick leave and personal), average employer contribution to retirement, etc. | F37: 0.3
C38: Resources: https://www.bankrate.com/finance/financial-literacy/the-value-of-employer-benefits.aspx https://www.griffinbenefits.com/employeebenefitsblog/what-does-the-average-employer-spend-on-employee-benefits
C39: Total Compensation | E39: =E32 * (1 + F34 + F37) -> 326660
C42: Marketing
C43: How much do you estimate your company will need to spend to acquire customers?
C44: Marketing Costs | F44: $
C45: How big do you expect your marketing costs to be? Examples: $1k - Logo, basic website, no app, no advertising $50k - Logo, basic website, with advertising $100k - Logo, basic website and app, with advertising $500k - Logo, complex website and app, with advertising | F45: 500000
C48: 6. Operational
C49: How much do you estimate your company will spend to operate?
C50: Administration | F50: $
C51: Legal, attorney, CPA/tax advisor and other professional consultants fees, insurances, etc... Consider about $5000 annually. For specific and detailed calculations, expand the + here on the left side column. | F51: 5000
C52: According to https://www.score.org/resource/infographic-look-accounting-and-taxes : 23% of small business owners spend $1,000 or less 31% Spend $1,000 to $5,000 18% Spend $5,000 to $10,000 12% Spend $10,000 to $20,000 16% Spend $20,000 or more
C53: Resources: CPA, Accountant https://www.cpapracticeadvisor.com/news/12300091/survey-shows-average-fees-for-accounting-tax-firm-services-for-2017 https://baranovcpa.ca/how-much-do-accountants-charge-for-a-small-business/ Insurances https://www.insureon.com/small-business-insurance/general-liability/cost https://fitsmallbusiness.com/commercial-property-insurance/
C54: Operative
C55: Inventory, raw materials, parts, equipment lease payments, etc... For tips, expand the + here on the left side column.
C56: Since this information is very specifically related to your kind of business, you should google for it. For instance, if you are in the food industry, to have an idea, you could google for “how much inventory should a restaurant carry”, or "average inventory turnover ratio for restaurant food", and so on.
C57: Expense | D57: Unit Cost | E57: Units | F57: Total
F58: =D58*E58 -> 0
F59: =D59*E59 -> 0
...

Sheet Market Sizing
B2: 5769 | C2: avg credit card spend / month
B4: 537000000 | C4: # of credit card accounts in the U.S
B5: =B4*B2 -> 3097953000000 | C5: TAM
B7: 72000000 | C7: # of millennials
B8: =B7*B2 -> 415368000000 | C8: SAM
B10: 0.005 | C10: Projected Yr 1 users as % of SOM
B11: =B10*B7 -> 360000
B12: =B11*B2 -> 2076840000 | C12: SOM

Sheet Market Sizing_updated
B2: =1.99*12 -> 23.88 | C2: annual subscription (year 1)
B4: 555360000 | C4: # of credit card accounts in the U.S
B5: 3 | C5: avg # of CCs / consumer
B6: =B4/B5 -> 185120000 | C6: avg # of credit card holders
B7: =B4*B2 -> 13261996800 | C7: TAM
B9: 0.4 | C9: share of millennials & older gen z who have CCs
B10: =B9*B6 -> 74048000 | C10: # of millennials & older genz w/ CCs
B11: =B9*B7 -> 5304798720 | C11: SAM
B13: 0.005 | C13: Projected Yr 1 users as % of SOM
B14: =B10*B13 -> 370240 | C14: SOM (users)
B15: =B13*B11 -> 26523994 | C15: SOM ($)
B16: =B14*B2 -> 8841331.2 | C16: projected year 1 revenue
B17: =B16/B15 -> 0.33333333 | C17: share of SOM
B20: https://www.finder.com/credit-card-statistics#source

Sheet Year 1
C4: Basic Financial Inventory
C5: How will you make & spend money?
C9: This spreadsheet will help you estimate how much money your business will make, and spend.
C13: Annual Revenue
C15: Customer Annual Value
C16: How much revenue do you estimate your company will make for each customer? | K16: 5769 | L16: avg credit card spend / month
C17: Product Price | F17: $ | K17: 0.015 | L17: fee that we would charge | N17: =5769*0.01 -> 57.69
C18: Price of Product=Average Monthly Credit Card Spend x Fee | F18: =K17*K16 -> 86.535 | K18: Product Price = 1% of average spend on CC
C19: Annual Purchases | F19: # Purchases | K19: =28050/2805000 -> 0.01 | L19: ='Market Sizing'!B11*K19 -> 3600 | M19: Projected Yr 1 users as % of SOM
C20: Number of purchases an average customer will make in a year. | F20: 12
C21: Total Number of Customers | F21: =L19 -> 3600
C22: Total Revenue | F22: =F18*F20*F21 -> 3738312
C27: Annual Expenses
C29: Salaries
C30: What will your future full time employees salary (and yours) be?
C31: Average Salary | E31: Salary | F31: Team Size
C32: What's the average salary you and your team members will make each year? | E32: 125506 | F32: 20
C33: Subtotal - Salaries | E33: =SUMPRODUCT(E32, F32) -> 2510120
C34: Taxes | F34: %
C35: Consider about 33% of the net salary (25% of gross salary) for: Federal taxes, Social Security and Medicare taxes. For specific and detailed calculations, expand the + here on the left side column. | F35: 0.3333
C36: Resources: https://www.thebalancesmb.com/payroll-taxes-3193126 http://web.mit.edu/e-club/hadzima/how-much-does-an-employee-cost.html
C37: Benefits Package | F37: %
C38: Consider about 30% of the net salary for benefits costs, such as paid leave (vacation, holidays, sick leave and personal), average employer contribution to retirement, etc. | F38: 0.3
C39: Resources: https://www.bankrate.com/finance/financial-literacy/the-value-of-employer-benefits.aspx https://www.griffinbenefits.com/employeebenefitsblog/what-does-the-average-employer-spend-on-employee-benefits
C40: Total Compensation | E40: =E33 * (1 + F35 + F38) -> 4099779
C43: Marketing
C44: How much do you estimate your company will need to spend to acquire customers?
C45: Marketing Costs | F45: $
C46: How big do you expect your marketing costs to be? Examples: $1,000 - Get a logo and a basic website $50,000 - Get all of the above plus advertising $100,000 - Get all of the above plus a simple app $500,000 - Get all of the above plus a complex app | F46: 500000
C49: 6. Operational
C50: How much do you estimate your company will spend to operate?
C51: Administration | F51: $
C52: Legal, attorney, CPA/tax advisor and other professional consultants fees, insurances, etc... Consider about $5000 annually. For specific and detailed calculations, expand the + here on the left side column. | F52: 5000
C53: According to https://www.score.org/resource/infographic-look-accounting-and-taxes : 23% of small business owners spend $1,000 or less 31% Spend $1,000 to $5,000 18% Spend $5,000 to $10,000 12% Spend $10,000 to $20,000 16% Spend $20,000 or more
C54: Resources: CPA, Accountant https://www.cpapracticeadvisor.com/news/12300091/survey-shows-average-fees-for-accounting-tax-firm-services-for-2017 https://baranovcpa.ca/how-much-do-accountants-charge-for-a-small-business/ Insurances https://www.insureon.com/small-business-insurance/general-liability/cost https://fitsmallbusiness.com/commercial-property-insurance/
C55: Operative
C56: Inventory, raw materials, parts, equipment lease payments, etc... For tips, expand the + here on the left side column.
C57: Since this information is very specifically related to your kind of business, you should google for it. For instance, if you are in the food industry, to have an idea, you could google for “how much inventory should a restaurant carry”, or "average inventory turnover ratio for restaurant food", and so on.
C58: Expense | D58: Unit Cost | E58: Units | F58: Total
C59: Laptop | D59: 1299 | E59: 20 | F59: =D59*E59 -> 25980
...

Sheet Year 2
C4: Basic Financial Inventory
C5: How will you make & spend money?
C9: This spreadsheet will help you estimate how much money your business will make, and spend.
C13: Annual Revenue
C15: Customer Annual Value
C16: How much revenue do you estimate your company will make for each customer? | K16: 5769 | L16: avg credit card spend / month (year 1)
C17: Product Price | F17: $ | K17: 0.05 | L17: predicted inflation rate
C18: Price of Product=Average Monthly Credit Card Spend x Fee | F18: =K16*(1+K17)*K18 -> 90.86175 | K18: 0.015 | L18: fee that we would charge
C19: Annual Purchases | F19: # Purchases
C20: Number of purchases an average customer will make in a year. | F20: 12
C21: Total Number of Customers | F21: ='Year 1'!F21*(1+K21) -> 6300 | K21: 0.75 | L21: customer growth
C22: Total Revenue | F22: =F18*F20*F21 -> 6869148.3
C27: Annual Expenses
C29: Salaries
C30: What will your future full time employees salary (and yours) be?
C31: Average Salary | E31: Salary | F31: Team Size
C32: What's the average salary you and your team members will make each year? | E32: =125506*1.1 -> 138056.6 | F32: 23 | K32: Team size increase + salary adjustment (10% salary increase)
C33: Subtotal - Salaries | E33: =SUMPRODUCT(E32, F32) -> 3175301.8
C34: Taxes | F34: %
C35: Consider about 33% of the net salary (25% of gross salary) for: Federal taxes, Social Security and Medicare taxes. For specific and detailed calculations, expand the + here on the left side column. | F35: 0.3333
C36: Resources: https://www.thebalancesmb.com/payroll-taxes-3193126 http://web.mit.edu/e-club/hadzima/how-much-does-an-employee-cost.html
C37: Benefits Package | F37: %
C38: Consider about 30% of the net salary for benefits costs, such as paid leave (vacation, holidays, sick leave and personal), average employer contribution to retirement, etc. | F38: 0.3
C39: Resources: https://www.bankrate.com/finance/financial-literacy/the-value-of-employer-benefits.aspx https://www.griffinbenefits.com/employeebenefitsblog/what-does-the-average-employer-spend-on-employee-benefits
C40: Total Compensation | E40: =E33 * (1 + F35 + F38) -> 5186220.4
C43: Marketing
C44: How much do you estimate your company will need to spend to acquire customers?
C45: Marketing Costs | F45: $
C46: How big do you expect your marketing costs to be? Examples: $1,000 - Get a logo and a basic website $50,000 - Get all of the above plus advertising $100,000 - Get all of the above plus a simple app $500,000 - Get all of the above plus a complex app | F46: 500000
C49: 6. Operational
C50: How much do you estimate your company will spend to operate?
C51: Administration | F51: $
C52: Legal, attorney, CPA/tax advisor and other professional consultants fees, insurances, etc... Consider about $5000 annually. For specific and detailed calculations, expand the + here on the left side column. | F52: 5000
C53: According to https://www.score.org/resource/infographic-look-accounting-and-taxes : 23% of small business owners spend $1,000 or less 31% Spend $1,000 to $5,000 18% Spend $5,000 to $10,000 12% Spend $10,000 to $20,000 16% Spend $20,000 or more
C54: Resources: CPA, Accountant https://www.cpapracticeadvisor.com/news/12300091/survey-shows-average-fees-for-accounting-tax-firm-services-for-2017 https://baranovcpa.ca/how-much-do-accountants-charge-for-a-small-business/ Insurances https://www.insureon.com/small-business-insurance/general-liability/cost https://fitsmallbusiness.com/commercial-property-insurance/
C55: Operative
C56: Inventory, raw materials, parts, equipment lease payments, etc... For tips, expand the + here on the left side column.
C57: Since this information is very specifically related to your kind of business, you should google for it. For instance, if you are in the food industry, to have an idea, you could google for “how much inventory should a restaurant carry”, or "average inventory turnover ratio for restaurant food", and so on.
C58: Expense | D58: Unit Cost | E58: Units | F58: Total
C59: laptop | D59: 1299 | E59: 3 | F59: =D59*E59 -> 3897
...

Sheet Year 3
C4: Basic Financial Inventory
C5: How will you make & spend money?
C9: This spreadsheet will help you estimate how much money your business will make, and spend.
C13: Annual Revenue
C15: Customer Annual Value
C16: How much revenue do you estimate your company will make for each customer? | K16: =5769*(1+'Year 2'!K17) -> 6057.45 | L16: avg credit card spend / month
C17: Product Price | F17: $ | K17: 0.05 | L17: predicted inflation rate
C18: Price of Product=Average Monthly Credit Card Spend x Fee | F18: =(K16*(1+K17))*K18 -> 95.404837 | K18: 0.015 | L18: fee that we would charge
C19: Annual Purchases | F19: # Purchases
C20: Number of purchases an average customer will make in a year. | F20: 12
C21: Total Number of Customers | F21: ='Year 2'!F21*(1+K21) -> 10080 | K21: 0.6 | L21: customer growth
C22: Total Revenue | F22: =F18*F20*F21 -> 11540169
C27: Annual Expenses
C29: Salaries
C30: What will your future full time employees salary (and yours) be?
C31: Average Salary | E31: Salary | F31: Team Size
C32: What's the average salary you and your team members will make each year? | E32: =(125506*1.1)*1.1 -> 151862.26 | F32: 33 | K32: Team size increase + salary adjustment (10% salary increase)
C33: Subtotal - Salaries | E33: =SUMPRODUCT(E32, F32) -> 5011454.6
C34: Taxes | F34: %
C35: Consider about 33% of the net salary (25% of gross salary) for: Federal taxes, Social Security and Medicare taxes. For specific and detailed calculations, expand the + here on the left side column. | F35: 0.3333
C36: Resources: https://www.thebalancesmb.com/payroll-taxes-3193126 http://web.mit.edu/e-club/hadzima/how-much-does-an-employee-cost.html
C37: Benefits Package | F37: %
C38: Consider about 30% of the net salary for benefits costs, such as paid leave (vacation, holidays, sick leave and personal), average employer contribution to retirement, etc. | F38: 0.3
C39: Resources: https://www.bankrate.com/finance/financial-literacy/the-value-of-employer-benefits.aspx https://www.griffinbenefits.com/employeebenefitsblog/what-does-the-average-employer-spend-on-employee-benefits
C40: Total Compensation | E40: =E33 * (1 + F35 + F38) -> 8185208.8
C43: Marketing
C44: How much do you estimate your company will need to spend to acquire customers?
C45: Marketing Costs | F45: $
C46: How big do you expect your marketing costs to be? Examples: $1,000 - Get a logo and a basic website $50,000 - Get all of the above plus advertising $100,000 - Get all of the above plus a simple app $500,000 - Get all of the above plus a complex app | F46: 500000
C49: 6. Operational
C50: How much do you estimate your company will spend to operate?
C51: Administration | F51: $
C52: Legal, attorney, CPA/tax advisor and other professional consultants fees, insurances, etc... Consider about $5000 annually. For specific and detailed calculations, expand the + here on the left side column. | F52: 5000
C53: According to https://www.score.org/resource/infographic-look-accounting-and-taxes : 23% of small business owners spend $1,000 or less 31% Spend $1,000 to $5,000 18% Spend $5,000 to $10,000 12% Spend $10,000 to $20,000 16% Spend $20,000 or more
C54: Resources: CPA, Accountant https://www.cpapracticeadvisor.com/news/12300091/survey-shows-average-fees-for-accounting-tax-firm-services-for-2017 https://baranovcpa.ca/how-much-do-accountants-charge-for-a-small-business/ Insurances https://www.insureon.com/small-business-insurance/general-liability/cost https://fitsmallbusiness.com/commercial-property-insurance/
C55: Operative
C56: Inventory, raw materials, parts, equipment lease payments, etc... For tips, expand the + here on the left side column.
C57: Since this information is very specifically related to your kind of business, you should google for it. For instance, if you are in the food industry, to have an idea, you could google for “how much inventory should a restaurant carry”, or "average inventory turnover ratio for restaurant food", and so on.
C58: Expense | D58: Unit Cost | E58: Units | F58: Total
C59: laptop | D59: 1299 | E59: 3 | F59: =D59*E59 -> 3897
...

Sheet Year 4
C4: Basic Financial Inventory
C5: How will you make & spend money?
C9: This spreadsheet will help you estimate how much money your business will make, and spend.
C13: Annual Revenue
C15: Customer Annual Value
C16: How much revenue do you estimate your company will make for each customer? | K16: =5769*(1+'Year 2'!K17)*(1+'Year 3'!K17) -> 6360.3225 | L16: avg credit card spend / month
C17: Product Price | F17: $ | K17: 0.04 | L17: predicted inflation rate
C18: Price of Product=Average Monthly Credit Card Spend x Fee | F18: =(K16*(1+K17))*K18 -> 99.221031 | K18: 0.015 | L18: fee that we would charge
C19: Annual Purchases | F19: # Purchases
C20: Number of purchases an average customer will make in a year. | F20: 12
C21: Total Number of Customers | F21: ='Year 3'!F21*(1+K21) -> 13104 | K21: 0.3 | L21: customer growth
C22: Total Revenue | F22: =F18*F20*F21 -> 15602309
C27: Annual Expenses
C29: Salaries
C30: What will your future full time employees salary (and yours) be?
C31: Average Salary | E31: Salary | F31: Team Size
C32: What's the average salary you and your team members will make each year? | E32: =((125506*1.1)*1.1)*1.1 -> 167048.49 | F32: 35 | K32: Team size increase + salary adjustment (10% salary increase)
C33: Subtotal - Salaries | E33: =SUMPRODUCT(E32, F32) -> 5846697
C34: Taxes | F34: %
C35: Consider about 33% of the net salary (25% of gross salary) for: Federal taxes, Social Security and Medicare taxes. For specific and detailed calculations, expand the + here on the left side column. | F35: 0.3333
C36: Resources: https://www.thebalancesmb.com/payroll-taxes-3193126 http://web.mit.edu/e-club/hadzima/how-much-does-an-employee-cost.html
C37: Benefits Package | F37: %
C38: Consider about 30% of the net salary for benefits costs, such as paid leave (vacation, holidays, sick leave and personal), average employer contribution to retirement, etc. | F38: 0.3
C39: Resources: https://www.bankrate.com/finance/financial-literacy/the-value-of-employer-benefits.aspx https://www.griffinbenefits.com/employeebenefitsblog/what-does-the-average-employer-spend-on-employee-benefits
C40: Total Compensation | E40: =E33 * (1 + F35 + F38) -> 9549410.2
C43: Marketing
C44: How much do you estimate your company will need to spend to acquire customers?
C45: Marketing Costs | F45: $
C46: How big do you expect your marketing costs to be? Examples: $1,000 - Get a logo and a basic website $50,000 - Get all of the above plus advertising $100,000 - Get all of the above plus a simple app $500,000 - Get all of the above plus a complex app | F46: 500000
C49: 6. Operational
C50: How much do you estimate your company will spend to operate?
C51: Administration | F51: $
C52: Legal, attorney, CPA/tax advisor and other professional consultants fees, insurances, etc... Consider about $5000 annually. For specific and detailed calculations, expand the + here on the left side column. | F52: 5000
C53: According to https://www.score.org/resource/infographic-look-accounting-and-taxes : 23% of small business owners spend $1,000 or less 31% Spend $1,000 to $5,000 18% Spend $5,000 to $10,000 12% Spend $10,000 to $20,000 16% Spend $20,000 or more
C54: Resources: CPA, Accountant https://www.cpapracticeadvisor.com/news/12300091/survey-shows-average-fees-for-accounting-tax-firm-services-for-2017 https://baranovcpa.ca/how-much-do-accountants-charge-for-a-small-business/ Insurances https://www.insureon.com/small-business-insurance/general-liability/cost https://fitsmallbusiness.com/commercial-property-insurance/
C55: Operative
C56: Inventory, raw materials, parts, equipment lease payments, etc... For tips, expand the + here on the left side column.
C57: Since this information is very specifically related to your kind of business, you should google for it. For instance, if you are in the food industry, to have an idea, you could google for “how much inventory should a restaurant carry”, or "average inventory turnover ratio for restaurant food", and so on.
C58: Expense | D58: Unit Cost | E58: Units | F58: Total
C59: laptop | D59: 1299 | E59: 2 | F59: =D59*E59 -> 2598
...

Sheet Year 5
C4: Basic Financial Inventory
C5: How will you make & spend money?
C9: This spreadsheet will help you estimate how much money your business will make, and spend.
C13: Annual Revenue
C15: Customer Annual Value
C16: How much revenue do you estimate your company will make for each customer? | K16: =5769*(1+'Year 2'!K17)*(1+'Year 3'!K17)*(1+'Year 4'!K17) -> 6614.7354 | L16: avg credit card spend / month year 1
C17: Product Price | F17: $ | K17: 0.03 | L17: predicted inflation rate
C18: Price of Product=Average Monthly Credit Card Spend x Fee | F18: =(K16*(1+K17))*K18 -> 102.19766 | K18: 0.015 | L18: fee that we would charge
C19: Annual Purchases | F19: # Purchases
C20: Number of purchases an average customer will make in a year. | F20: 12
C21: Total Number of Customers | F21: ='Year 4'!F21*(1+K21) -> 17690.4 | K21: 0.35 | L21: customer growth
C22: Total Revenue | F22: =F18*F20*F21 -> 21695010
C27: Annual Expenses
C29: Salaries
C30: What will your future full time employees salary (and yours) be?
C31: Average Salary | E31: Salary | F31: Team Size
C32: What's the average salary you and your team members will make each year? | E32: =(((125506*1.1)*1.1)*1.1)*1.1 -> 183753.33 | F32: 38 | K32: Team size increase + salary adjustment (10% salary increase)
C33: Subtotal - Salaries | E33: =SUMPRODUCT(E32, F32) -> 6982626.7
C34: Taxes | F34: %
C35: Consider about 33% of the net salary (25% of gross salary) for: Federal taxes, Social Security and Medicare taxes. For specific and detailed calculations, expand the + here on the left side column. | F35: 0.3333
C36: Resources: https://www.thebalancesmb.com/payroll-taxes-3193126 http://web.mit.edu/e-club/hadzima/how-much-does-an-employee-cost.html
C37: Benefits Package | F37: %
C38: Consider about 30% of the net salary for benefits costs, such as paid leave (vacation, holidays, sick leave and personal), average employer contribution to retirement, etc. | F38: 0.3
C39: Resources: https://www.bankrate.com/finance/financial-literacy/the-value-of-employer-benefits.aspx https://www.griffinbenefits.com/employeebenefitsblog/what-does-the-average-employer-spend-on-employee-benefits
C40: Total Compensation | E40: =E33 * (1 + F35 + F38) -> 11404724
C43: Marketing
C44: How much do you estimate your company will need to spend to acquire customers?
C45: Marketing Costs | F45: $
C46: How big do you expect your marketing costs to be? Examples: $1,000 - Get a logo and a basic website $50,000 - Get all of the above plus advertising $100,000 - Get all of the above plus a simple app $500,000 - Get all of the above plus a complex app | F46: 500000
C49: 6. Operational
C50: How much do you estimate your company will spend to operate?
C51: Administration | F51: $
C52: Legal, attorney, CPA/tax advisor and other professional consultants fees, insurances, etc... Consider about $5000 annually. For specific and detailed calculations, expand the + here on the left side column. | F52: 5000
C53: According to https://www.score.org/resource/infographic-look-accounting-and-taxes : 23% of small business owners spend $1,000 or less 31% Spend $1,000 to $5,000 18% Spend $5,000 to $10,000 12% Spend $10,000 to $20,000 16% Spend $20,000 or more
C54: Resources: CPA, Accountant https://www.cpapracticeadvisor.com/news/12300091/survey-shows-average-fees-for-accounting-tax-firm-services-for-2017 https://baranovcpa.ca/how-much-do-accountants-charge-for-a-small-business/ Insurances https://www.insureon.com/small-business-insurance/general-liability/cost https://fitsmallbusiness.com/commercial-property-insurance/
C55: Operative
C56: Inventory, raw materials, parts, equipment lease payments, etc... For tips, expand the + here on the left side column.
C57: Since this information is very specifically related to your kind of business, you should google for it. For instance, if you are in the food industry, to have an idea, you could google for “how much inventory should a restaurant carry”, or "average inventory turnover ratio for restaurant food", and so on.
C58: Expense | D58: Unit Cost | E58: Units | F58: Total
C59: laptop | D59: 1299 | E59: 3 | F59: =D59*E59 -> 3897
...

Sheet Financial Statement
C2: Year 1 | D2: Year 2 | E2: Year 3 | F2: Year 4 | G2: Year 5
B3: Average Monthly Credit Card Spend | C3: 5769 | D3: =C3*(1+D22) -> 6057.45 | E3: =D3*(1+E22) -> 6360.3225 | F3: =E3*(1+F22) -> 6614.7354 | G3: =F3*(1+G22) -> 6813.1775
B4: Fee | C4: 0.015 | D4: 0.015 | E4: 0.015 | F4: 0.015 | G4: 0.015
B5: Product Price | C5: =C3*C4 -> 86.535 | D5: =D3*D4 -> 90.86175 | E5: =E3*E4 -> 95.404837 | F5: =F3*F4 -> 99.221031 | G5: =G3*G4 -> 102.19766
B6: Total Number of Customers | C6: ='Year 1'!F21 -> 3600 | D6: =C6*(1+D23) -> 6300 | E6: =D6*(1+E23) -> 10080 | F6: =E6*(1+F23) -> 13104 | G6: =F6*(1+G23) -> 17690.4
B7: Total Revenue | C7: =C5*C6*C21 -> 3738312 | D7: =D5*D6*D21 -> 6869148.3 | E7: =E5*E6*E21 -> 11540169 | F7: =F5*F6*F21 -> 15602309 | G7: =G5*G6*G21 -> 21695010
B8: Revenue Growth (%) | C8: N/A | D8: =D7/C7-1 -> 0.8375 | E8: =E7/D7-1 -> 0.68 | F8: =F7/E7-1 -> 0.352 | G8: =G7/F7-1 -> 0.3905
B10: Compensation | C10: ='Year 1'!E40 -> 4099779 | D10: ='Year 2'!E40 -> 5186220.4 | E10: ='Year 3'!E40 -> 8185208.8 | F10: ='Year 4'!E40 -> 9549410.2 | G10: ='Year 5'!E40 -> 11404724
B11: Marketing | C11: ='Year 1'!F46 -> 500000 | D11: =$C$11 -> 500000 | E11: =$C$11 -> 500000 | F11: =$C$11 -> 500000 | G11: =$C$11 -> 500000
B12: Admin | C12: 5000 | D12: 5000 | E12: 5000 | F12: 5000 | G12: 5000
B13: Other Operating Expenses | C13: ='Year 1'!F66 -> 30337980 | D13: ='Year 2'!F66 -> 30446241 | E13: ='Year 3'!F66 -> 29365548 | F13: ='Year 4'!F66 -> 30513806 | G13: ='Year 5'!F66 -> 25995499
B14: Total Expenses | C14: =SUM(C10:C13) -> 34942759 | D14: =SUM(D10:D13) -> 36137462 | E14: =SUM(E10:E13) -> 38055757 | F14: =SUM(F10:F13) -> 40568216 | G14: =SUM(G10:G13) -> 37905223
B16: Net Profit | C16: =C7-C14 -> -31204447 | D16: =D7-D14 -> -29268314 | E16: =E7-E14 -> -26515587 | F16: =F7-F14 -> -24965908 | G16: =G7-G14 -> -16210213
C17: =C7/C14 -> 0.10698388
B21: Number of purchases per year | C21: 12 | D21: =C21 -> 12 | E21: =D21 -> 12 | F21: =E21 -> 12 | G21: =F21 -> 12
B22: Predicted Inflation Rate | C22: N/A | D22: 0.05 | E22: 0.05 | F22: 0.04 | G22: 0.03
B23: Customer Growth | C23: N/A | D23: 0.75 | E23: 0.6 | F23: 0.3 | G23: 0.35

Sheet Financial Statement (2)
C2: Year 1 | D2: Year 2 | E2: Year 3 | F2: Year 4 | G2: Year 5
B3: Subscription Fee | C3: 1.99 | D3: =C3 -> 1.99 | E3: =D3 -> 1.99 | F3: 2.99 | G3: 2.99
B4: Total Number of Customers | C4: ='Market Sizing_updated'!B14 -> 370240 | D4: =C4*(1+D21) -> 740480 | E4: =D4*(1+E21) -> 1110720 | F4: =E4*(1+F21) -> 1388400 | G4: =F4*(1+G21) -> 1596660
B5: Total Revenue | C5: =(C3*12)*C4 -> 8841331.2 | D5: =D3*D4*D19 -> 17682662 | E5: =E3*E4*E19 -> 26523994 | F5: =F3*F4*F19 -> 49815792 | G5: =G3*G4*G19 -> 57288161
B6: Revenue Growth (%) | C6: N/A | D6: =D5/C5-1 -> 1 | E6: =E5/D5-1 -> 0.5 | F6: =F5/E5-1 -> 0.8781407 | G6: =G5/F5-1 -> 0.15
B8: Compensation | C8: ='Year 1'!E40 -> 4099779 | D8: ='Year 2'!E40 -> 5186220.4 | E8: ='Year 3'!E40 -> 8185208.8 | F8: ='Year 4'!E40 -> 9549410.2 | G8: ='Year 5'!E40 -> 11404724
B9: Marketing | C9: ='Year 1'!F46 -> 500000 | D9: =$C$9 -> 500000 | E9: =$C$9 -> 500000 | F9: =$C$9 -> 500000 | G9: =$C$9 -> 500000
B10: Admin | C10: 5000 | D10: 5000 | E10: 5000 | F10: 5000 | G10: 5000
B11: Other Operating Expenses | C11: ='Year 1'!F66 -> 30337980 | D11: ='Year 2'!F66 -> 30446241 | E11: ='Year 3'!F66 -> 29365548 | F11: ='Year 4'!F66 -> 30513806 | G11: ='Year 5'!F66 -> 25995499
B12: Total Expenses | C12: =SUM(C8:C11) -> 34942759 | D12: =SUM(D8:D11) -> 36137462 | E12: =SUM(E8:E11) -> 38055757 | F12: =SUM(F8:F11) -> 40568216 | G12: =SUM(G8:G11) -> 37905223
B14: Net Profit | C14: =C5-C12 -> -26101428 | D14: =D5-D12 -> -18454800 | E14: =E5-E12 -> -11531763 | F14: =F5-F12 -> 9247575.7 | G14: =G5-G12 -> 19382938
C15: =C5/C12 -> 0.25302327
B19: Number of purchases per year | C19: 12 | D19: =C19 -> 12 | E19: =D19 -> 12 | F19: =E19 -> 12 | G19: =F19 -> 12
B20: Predicted Inflation Rate | C20: N/A | D20: 0.05 | E20: 0.05 | F20: 0.04 | G20: 0.03
B21: Customer Growth | C21: N/A | D21: 1 | E21: 0.5 | F21: 0.25 | G21: 0.15
B23: Source for customer growth
B24: https://www.linkedin.com/pulse/growth-rate-startups-united-states-eqvista/

Sheet Variables
A1: Marketing Cost Options
A2: 1000
A3: 50000
A4: 100000
A5: 500000
